[2024-11-25T23:46:10.079+0000] {processor.py:161} INFO - Started process (PID=212) to work on /opt/airflow/dags/daily_data_etl.py
[2024-11-25T23:46:10.080+0000] {processor.py:830} INFO - Processing file /opt/airflow/dags/daily_data_etl.py for tasks to queue
[2024-11-25T23:46:10.082+0000] {logging_mixin.py:188} INFO - [2024-11-25T23:46:10.082+0000] {dagbag.py:545} INFO - Filling up the DagBag from /opt/airflow/dags/daily_data_etl.py
[2024-11-25T23:46:10.095+0000] {logging_mixin.py:188} INFO - [2024-11-25T23:46:10.091+0000] {dagbag.py:355} ERROR - Failed to import: /opt/airflow/dags/daily_data_etl.py
Traceback (most recent call last):
  File "/home/airflow/.local/lib/python3.12/site-packages/airflow/models/dagbag.py", line 351, in parse
    loader.exec_module(new_module)
  File "<frozen importlib._bootstrap_external>", line 995, in exec_module
  File "<frozen importlib._bootstrap>", line 488, in _call_with_frames_removed
  File "/opt/airflow/dags/daily_data_etl.py", line 6, in <module>
    from airflow.utils.context import get_current_context
ImportError: cannot import name 'get_current_context' from 'airflow.utils.context' (/home/airflow/.local/lib/python3.12/site-packages/airflow/utils/context.py)
[2024-11-25T23:46:10.097+0000] {processor.py:842} WARNING - No viable dags retrieved from /opt/airflow/dags/daily_data_etl.py
[2024-11-25T23:46:10.114+0000] {processor.py:183} INFO - Processing /opt/airflow/dags/daily_data_etl.py took 0.040 seconds
[2024-11-25T23:46:40.340+0000] {processor.py:161} INFO - Started process (PID=266) to work on /opt/airflow/dags/daily_data_etl.py
[2024-11-25T23:46:40.341+0000] {processor.py:830} INFO - Processing file /opt/airflow/dags/daily_data_etl.py for tasks to queue
[2024-11-25T23:46:40.344+0000] {logging_mixin.py:188} INFO - [2024-11-25T23:46:40.343+0000] {dagbag.py:545} INFO - Filling up the DagBag from /opt/airflow/dags/daily_data_etl.py
[2024-11-25T23:46:40.367+0000] {logging_mixin.py:188} INFO - [2024-11-25T23:46:40.360+0000] {dagbag.py:355} ERROR - Failed to import: /opt/airflow/dags/daily_data_etl.py
Traceback (most recent call last):
  File "/home/airflow/.local/lib/python3.12/site-packages/airflow/models/dagbag.py", line 351, in parse
    loader.exec_module(new_module)
  File "<frozen importlib._bootstrap_external>", line 995, in exec_module
  File "<frozen importlib._bootstrap>", line 488, in _call_with_frames_removed
  File "/opt/airflow/dags/daily_data_etl.py", line 6, in <module>
    from airflow.utils.context import get_current_context
ImportError: cannot import name 'get_current_context' from 'airflow.utils.context' (/home/airflow/.local/lib/python3.12/site-packages/airflow/utils/context.py)
[2024-11-25T23:46:40.370+0000] {processor.py:842} WARNING - No viable dags retrieved from /opt/airflow/dags/daily_data_etl.py
[2024-11-25T23:46:40.405+0000] {processor.py:183} INFO - Processing /opt/airflow/dags/daily_data_etl.py took 0.071 seconds
[2024-11-25T23:47:10.526+0000] {processor.py:161} INFO - Started process (PID=287) to work on /opt/airflow/dags/daily_data_etl.py
[2024-11-25T23:47:10.527+0000] {processor.py:830} INFO - Processing file /opt/airflow/dags/daily_data_etl.py for tasks to queue
[2024-11-25T23:47:10.528+0000] {logging_mixin.py:188} INFO - [2024-11-25T23:47:10.528+0000] {dagbag.py:545} INFO - Filling up the DagBag from /opt/airflow/dags/daily_data_etl.py
[2024-11-25T23:47:10.541+0000] {logging_mixin.py:188} INFO - [2024-11-25T23:47:10.538+0000] {dagbag.py:355} ERROR - Failed to import: /opt/airflow/dags/daily_data_etl.py
Traceback (most recent call last):
  File "/home/airflow/.local/lib/python3.12/site-packages/airflow/models/dagbag.py", line 351, in parse
    loader.exec_module(new_module)
  File "<frozen importlib._bootstrap_external>", line 995, in exec_module
  File "<frozen importlib._bootstrap>", line 488, in _call_with_frames_removed
  File "/opt/airflow/dags/daily_data_etl.py", line 6, in <module>
    from airflow.utils.context import get_current_context
ImportError: cannot import name 'get_current_context' from 'airflow.utils.context' (/home/airflow/.local/lib/python3.12/site-packages/airflow/utils/context.py)
[2024-11-25T23:47:10.543+0000] {processor.py:842} WARNING - No viable dags retrieved from /opt/airflow/dags/daily_data_etl.py
[2024-11-25T23:47:10.559+0000] {processor.py:183} INFO - Processing /opt/airflow/dags/daily_data_etl.py took 0.039 seconds
[2024-11-25T23:47:40.714+0000] {processor.py:161} INFO - Started process (PID=303) to work on /opt/airflow/dags/daily_data_etl.py
[2024-11-25T23:47:40.715+0000] {processor.py:830} INFO - Processing file /opt/airflow/dags/daily_data_etl.py for tasks to queue
[2024-11-25T23:47:40.716+0000] {logging_mixin.py:188} INFO - [2024-11-25T23:47:40.716+0000] {dagbag.py:545} INFO - Filling up the DagBag from /opt/airflow/dags/daily_data_etl.py
[2024-11-25T23:47:40.728+0000] {logging_mixin.py:188} INFO - [2024-11-25T23:47:40.725+0000] {dagbag.py:355} ERROR - Failed to import: /opt/airflow/dags/daily_data_etl.py
Traceback (most recent call last):
  File "/home/airflow/.local/lib/python3.12/site-packages/airflow/models/dagbag.py", line 351, in parse
    loader.exec_module(new_module)
  File "<frozen importlib._bootstrap_external>", line 995, in exec_module
  File "<frozen importlib._bootstrap>", line 488, in _call_with_frames_removed
  File "/opt/airflow/dags/daily_data_etl.py", line 6, in <module>
    from airflow.utils.context import get_current_context
ImportError: cannot import name 'get_current_context' from 'airflow.utils.context' (/home/airflow/.local/lib/python3.12/site-packages/airflow/utils/context.py)
[2024-11-25T23:47:40.730+0000] {processor.py:842} WARNING - No viable dags retrieved from /opt/airflow/dags/daily_data_etl.py
[2024-11-25T23:47:40.746+0000] {processor.py:183} INFO - Processing /opt/airflow/dags/daily_data_etl.py took 0.037 seconds
[2024-11-25T23:48:16.218+0000] {processor.py:161} INFO - Started process (PID=206) to work on /opt/airflow/dags/daily_data_etl.py
[2024-11-25T23:48:16.219+0000] {processor.py:830} INFO - Processing file /opt/airflow/dags/daily_data_etl.py for tasks to queue
[2024-11-25T23:48:16.220+0000] {logging_mixin.py:188} INFO - [2024-11-25T23:48:16.220+0000] {dagbag.py:545} INFO - Filling up the DagBag from /opt/airflow/dags/daily_data_etl.py
[2024-11-25T23:48:16.236+0000] {logging_mixin.py:188} INFO - [2024-11-25T23:48:16.232+0000] {dagbag.py:355} ERROR - Failed to import: /opt/airflow/dags/daily_data_etl.py
Traceback (most recent call last):
  File "/home/airflow/.local/lib/python3.12/site-packages/airflow/models/dagbag.py", line 351, in parse
    loader.exec_module(new_module)
  File "<frozen importlib._bootstrap_external>", line 995, in exec_module
  File "<frozen importlib._bootstrap>", line 488, in _call_with_frames_removed
  File "/opt/airflow/dags/daily_data_etl.py", line 6, in <module>
    from airflow.utils.context import get_current_context
ImportError: cannot import name 'get_current_context' from 'airflow.utils.context' (/home/airflow/.local/lib/python3.12/site-packages/airflow/utils/context.py)
[2024-11-25T23:48:16.238+0000] {processor.py:842} WARNING - No viable dags retrieved from /opt/airflow/dags/daily_data_etl.py
[2024-11-25T23:48:16.257+0000] {processor.py:183} INFO - Processing /opt/airflow/dags/daily_data_etl.py took 0.045 seconds
[2024-11-25T23:48:46.460+0000] {processor.py:161} INFO - Started process (PID=255) to work on /opt/airflow/dags/daily_data_etl.py
[2024-11-25T23:48:46.462+0000] {processor.py:830} INFO - Processing file /opt/airflow/dags/daily_data_etl.py for tasks to queue
[2024-11-25T23:48:46.467+0000] {logging_mixin.py:188} INFO - [2024-11-25T23:48:46.466+0000] {dagbag.py:545} INFO - Filling up the DagBag from /opt/airflow/dags/daily_data_etl.py
[2024-11-25T23:48:46.486+0000] {logging_mixin.py:188} INFO - [2024-11-25T23:48:46.481+0000] {dagbag.py:355} ERROR - Failed to import: /opt/airflow/dags/daily_data_etl.py
Traceback (most recent call last):
  File "/home/airflow/.local/lib/python3.12/site-packages/airflow/models/dagbag.py", line 351, in parse
    loader.exec_module(new_module)
  File "<frozen importlib._bootstrap_external>", line 995, in exec_module
  File "<frozen importlib._bootstrap>", line 488, in _call_with_frames_removed
  File "/opt/airflow/dags/daily_data_etl.py", line 6, in <module>
    from airflow.utils.context import get_current_context
ImportError: cannot import name 'get_current_context' from 'airflow.utils.context' (/home/airflow/.local/lib/python3.12/site-packages/airflow/utils/context.py)
[2024-11-25T23:48:46.490+0000] {processor.py:842} WARNING - No viable dags retrieved from /opt/airflow/dags/daily_data_etl.py
[2024-11-25T23:48:46.534+0000] {processor.py:183} INFO - Processing /opt/airflow/dags/daily_data_etl.py took 0.084 seconds
[2024-11-25T23:49:16.951+0000] {processor.py:161} INFO - Started process (PID=271) to work on /opt/airflow/dags/daily_data_etl.py
[2024-11-25T23:49:16.951+0000] {processor.py:830} INFO - Processing file /opt/airflow/dags/daily_data_etl.py for tasks to queue
[2024-11-25T23:49:16.953+0000] {logging_mixin.py:188} INFO - [2024-11-25T23:49:16.953+0000] {dagbag.py:545} INFO - Filling up the DagBag from /opt/airflow/dags/daily_data_etl.py
[2024-11-25T23:49:16.964+0000] {logging_mixin.py:188} INFO - [2024-11-25T23:49:16.961+0000] {dagbag.py:355} ERROR - Failed to import: /opt/airflow/dags/daily_data_etl.py
Traceback (most recent call last):
  File "/home/airflow/.local/lib/python3.12/site-packages/airflow/models/dagbag.py", line 351, in parse
    loader.exec_module(new_module)
  File "<frozen importlib._bootstrap_external>", line 995, in exec_module
  File "<frozen importlib._bootstrap>", line 488, in _call_with_frames_removed
  File "/opt/airflow/dags/daily_data_etl.py", line 6, in <module>
    from airflow.utils.context import get_current_context
ImportError: cannot import name 'get_current_context' from 'airflow.utils.context' (/home/airflow/.local/lib/python3.12/site-packages/airflow/utils/context.py)
[2024-11-25T23:49:16.965+0000] {processor.py:842} WARNING - No viable dags retrieved from /opt/airflow/dags/daily_data_etl.py
[2024-11-25T23:49:16.979+0000] {processor.py:183} INFO - Processing /opt/airflow/dags/daily_data_etl.py took 0.033 seconds
[2024-11-25T23:49:47.434+0000] {processor.py:161} INFO - Started process (PID=287) to work on /opt/airflow/dags/daily_data_etl.py
[2024-11-25T23:49:47.435+0000] {processor.py:830} INFO - Processing file /opt/airflow/dags/daily_data_etl.py for tasks to queue
[2024-11-25T23:49:47.436+0000] {logging_mixin.py:188} INFO - [2024-11-25T23:49:47.436+0000] {dagbag.py:545} INFO - Filling up the DagBag from /opt/airflow/dags/daily_data_etl.py
[2024-11-25T23:49:47.448+0000] {logging_mixin.py:188} INFO - [2024-11-25T23:49:47.445+0000] {dagbag.py:355} ERROR - Failed to import: /opt/airflow/dags/daily_data_etl.py
Traceback (most recent call last):
  File "/home/airflow/.local/lib/python3.12/site-packages/airflow/models/dagbag.py", line 351, in parse
    loader.exec_module(new_module)
  File "<frozen importlib._bootstrap_external>", line 995, in exec_module
  File "<frozen importlib._bootstrap>", line 488, in _call_with_frames_removed
  File "/opt/airflow/dags/daily_data_etl.py", line 6, in <module>
    from airflow.utils.context import get_current_context
ImportError: cannot import name 'get_current_context' from 'airflow.utils.context' (/home/airflow/.local/lib/python3.12/site-packages/airflow/utils/context.py)
[2024-11-25T23:49:47.449+0000] {processor.py:842} WARNING - No viable dags retrieved from /opt/airflow/dags/daily_data_etl.py
[2024-11-25T23:49:47.463+0000] {processor.py:183} INFO - Processing /opt/airflow/dags/daily_data_etl.py took 0.033 seconds
[2024-11-25T23:50:18.026+0000] {processor.py:161} INFO - Started process (PID=303) to work on /opt/airflow/dags/daily_data_etl.py
[2024-11-25T23:50:18.027+0000] {processor.py:830} INFO - Processing file /opt/airflow/dags/daily_data_etl.py for tasks to queue
[2024-11-25T23:50:18.028+0000] {logging_mixin.py:188} INFO - [2024-11-25T23:50:18.028+0000] {dagbag.py:545} INFO - Filling up the DagBag from /opt/airflow/dags/daily_data_etl.py
[2024-11-25T23:50:18.039+0000] {logging_mixin.py:188} INFO - [2024-11-25T23:50:18.036+0000] {dagbag.py:355} ERROR - Failed to import: /opt/airflow/dags/daily_data_etl.py
Traceback (most recent call last):
  File "/home/airflow/.local/lib/python3.12/site-packages/airflow/models/dagbag.py", line 351, in parse
    loader.exec_module(new_module)
  File "<frozen importlib._bootstrap_external>", line 995, in exec_module
  File "<frozen importlib._bootstrap>", line 488, in _call_with_frames_removed
  File "/opt/airflow/dags/daily_data_etl.py", line 6, in <module>
    from airflow.utils.context import get_current_context
ImportError: cannot import name 'get_current_context' from 'airflow.utils.context' (/home/airflow/.local/lib/python3.12/site-packages/airflow/utils/context.py)
[2024-11-25T23:50:18.041+0000] {processor.py:842} WARNING - No viable dags retrieved from /opt/airflow/dags/daily_data_etl.py
[2024-11-25T23:50:18.055+0000] {processor.py:183} INFO - Processing /opt/airflow/dags/daily_data_etl.py took 0.033 seconds
[2024-11-25T23:50:44.925+0000] {processor.py:161} INFO - Started process (PID=319) to work on /opt/airflow/dags/daily_data_etl.py
[2024-11-25T23:50:44.925+0000] {processor.py:830} INFO - Processing file /opt/airflow/dags/daily_data_etl.py for tasks to queue
[2024-11-25T23:50:44.927+0000] {logging_mixin.py:188} INFO - [2024-11-25T23:50:44.927+0000] {dagbag.py:545} INFO - Filling up the DagBag from /opt/airflow/dags/daily_data_etl.py
[2024-11-25T23:50:44.948+0000] {logging_mixin.py:188} INFO - [2024-11-25T23:50:44.948+0000] {base.py:84} INFO - Using connection ID 'snowflake_conn_nba' for task execution.
[2024-11-25T23:50:44.949+0000] {logging_mixin.py:188} INFO - [2024-11-25T23:50:44.949+0000] {connection.py:399} INFO - Snowflake Connector for Python Version: 3.10.0, Python Version: 3.12.3, Platform: Linux-5.15.153.1-microsoft-standard-WSL2-x86_64-with-glibc2.36
[2024-11-25T23:50:44.950+0000] {logging_mixin.py:188} INFO - [2024-11-25T23:50:44.950+0000] {connection.py:1239} INFO - This connection is in OCSP Fail Open Mode. TLS Certificates would be checked for validity and revocation status. Any other Certificate Revocation related exceptions or OCSP Responder failures would be disregarded in favor of connectivity.
[2024-11-25T23:50:45.409+0000] {logging_mixin.py:188} INFO - [2024-11-25T23:50:45.407+0000] {dagbag.py:355} ERROR - Failed to import: /opt/airflow/dags/daily_data_etl.py
Traceback (most recent call last):
  File "/home/airflow/.local/lib/python3.12/site-packages/airflow/models/dagbag.py", line 351, in parse
    loader.exec_module(new_module)
  File "<frozen importlib._bootstrap_external>", line 995, in exec_module
  File "<frozen importlib._bootstrap>", line 488, in _call_with_frames_removed
  File "/opt/airflow/dags/daily_data_etl.py", line 159, in <module>
    rapid_api_key = Variable.get("rapid_api_key")
                    ^^^^^^^^^^^^^^^^^^^^^^^^^^^^^
  File "/home/airflow/.local/lib/python3.12/site-packages/airflow/models/variable.py", line 143, in get
    raise KeyError(f"Variable {key} does not exist")
KeyError: 'Variable rapid_api_key does not exist'
[2024-11-25T23:50:45.410+0000] {processor.py:842} WARNING - No viable dags retrieved from /opt/airflow/dags/daily_data_etl.py
[2024-11-25T23:50:45.417+0000] {processor.py:183} INFO - Processing /opt/airflow/dags/daily_data_etl.py took 0.497 seconds
[2024-11-25T23:51:29.628+0000] {processor.py:161} INFO - Started process (PID=206) to work on /opt/airflow/dags/daily_data_etl.py
[2024-11-25T23:51:29.629+0000] {processor.py:830} INFO - Processing file /opt/airflow/dags/daily_data_etl.py for tasks to queue
[2024-11-25T23:51:29.631+0000] {logging_mixin.py:188} INFO - [2024-11-25T23:51:29.631+0000] {dagbag.py:545} INFO - Filling up the DagBag from /opt/airflow/dags/daily_data_etl.py
[2024-11-25T23:51:29.657+0000] {logging_mixin.py:188} INFO - [2024-11-25T23:51:29.657+0000] {base.py:84} INFO - Using connection ID 'snowflake_conn_nba' for task execution.
[2024-11-25T23:51:29.658+0000] {logging_mixin.py:188} INFO - [2024-11-25T23:51:29.658+0000] {connection.py:399} INFO - Snowflake Connector for Python Version: 3.10.0, Python Version: 3.12.3, Platform: Linux-5.15.153.1-microsoft-standard-WSL2-x86_64-with-glibc2.36
[2024-11-25T23:51:29.660+0000] {logging_mixin.py:188} INFO - [2024-11-25T23:51:29.659+0000] {connection.py:1239} INFO - This connection is in OCSP Fail Open Mode. TLS Certificates would be checked for validity and revocation status. Any other Certificate Revocation related exceptions or OCSP Responder failures would be disregarded in favor of connectivity.
[2024-11-25T23:51:30.310+0000] {logging_mixin.py:188} INFO - [2024-11-25T23:51:30.307+0000] {dagbag.py:355} ERROR - Failed to import: /opt/airflow/dags/daily_data_etl.py
Traceback (most recent call last):
  File "/home/airflow/.local/lib/python3.12/site-packages/airflow/models/dagbag.py", line 351, in parse
    loader.exec_module(new_module)
  File "<frozen importlib._bootstrap_external>", line 995, in exec_module
  File "<frozen importlib._bootstrap>", line 488, in _call_with_frames_removed
  File "/opt/airflow/dags/daily_data_etl.py", line 159, in <module>
    rapid_api_key = Variable.get("rapid_api_key")
                    ^^^^^^^^^^^^^^^^^^^^^^^^^^^^^
  File "/home/airflow/.local/lib/python3.12/site-packages/airflow/models/variable.py", line 143, in get
    raise KeyError(f"Variable {key} does not exist")
KeyError: 'Variable rapid_api_key does not exist'
[2024-11-25T23:51:30.311+0000] {processor.py:842} WARNING - No viable dags retrieved from /opt/airflow/dags/daily_data_etl.py
[2024-11-25T23:51:30.320+0000] {processor.py:183} INFO - Processing /opt/airflow/dags/daily_data_etl.py took 0.696 seconds
[2024-11-25T23:52:01.207+0000] {processor.py:161} INFO - Started process (PID=255) to work on /opt/airflow/dags/daily_data_etl.py
[2024-11-25T23:52:01.208+0000] {processor.py:830} INFO - Processing file /opt/airflow/dags/daily_data_etl.py for tasks to queue
[2024-11-25T23:52:01.209+0000] {logging_mixin.py:188} INFO - [2024-11-25T23:52:01.209+0000] {dagbag.py:545} INFO - Filling up the DagBag from /opt/airflow/dags/daily_data_etl.py
[2024-11-25T23:52:01.231+0000] {logging_mixin.py:188} INFO - [2024-11-25T23:52:01.230+0000] {base.py:84} INFO - Using connection ID 'snowflake_conn_nba' for task execution.
[2024-11-25T23:52:01.232+0000] {logging_mixin.py:188} INFO - [2024-11-25T23:52:01.231+0000] {connection.py:399} INFO - Snowflake Connector for Python Version: 3.10.0, Python Version: 3.12.3, Platform: Linux-5.15.153.1-microsoft-standard-WSL2-x86_64-with-glibc2.36
[2024-11-25T23:52:01.232+0000] {logging_mixin.py:188} INFO - [2024-11-25T23:52:01.232+0000] {connection.py:1239} INFO - This connection is in OCSP Fail Open Mode. TLS Certificates would be checked for validity and revocation status. Any other Certificate Revocation related exceptions or OCSP Responder failures would be disregarded in favor of connectivity.
[2024-11-25T23:52:02.000+0000] {logging_mixin.py:188} INFO - [2024-11-25T23:52:01.997+0000] {dagbag.py:355} ERROR - Failed to import: /opt/airflow/dags/daily_data_etl.py
Traceback (most recent call last):
  File "/home/airflow/.local/lib/python3.12/site-packages/airflow/models/dagbag.py", line 351, in parse
    loader.exec_module(new_module)
  File "<frozen importlib._bootstrap_external>", line 995, in exec_module
  File "<frozen importlib._bootstrap>", line 488, in _call_with_frames_removed
  File "/opt/airflow/dags/daily_data_etl.py", line 159, in <module>
    rapid_api_key = Variable.get("rapid_api_key")
                    ^^^^^^^^^^^^^^^^^^^^^^^^^^^^^
  File "/home/airflow/.local/lib/python3.12/site-packages/airflow/models/variable.py", line 143, in get
    raise KeyError(f"Variable {key} does not exist")
KeyError: 'Variable rapid_api_key does not exist'
[2024-11-25T23:52:02.001+0000] {processor.py:842} WARNING - No viable dags retrieved from /opt/airflow/dags/daily_data_etl.py
[2024-11-25T23:52:02.008+0000] {processor.py:183} INFO - Processing /opt/airflow/dags/daily_data_etl.py took 0.805 seconds
[2024-11-25T23:52:32.851+0000] {processor.py:161} INFO - Started process (PID=271) to work on /opt/airflow/dags/daily_data_etl.py
[2024-11-25T23:52:32.852+0000] {processor.py:830} INFO - Processing file /opt/airflow/dags/daily_data_etl.py for tasks to queue
[2024-11-25T23:52:32.854+0000] {logging_mixin.py:188} INFO - [2024-11-25T23:52:32.854+0000] {dagbag.py:545} INFO - Filling up the DagBag from /opt/airflow/dags/daily_data_etl.py
[2024-11-25T23:52:32.879+0000] {logging_mixin.py:188} INFO - [2024-11-25T23:52:32.878+0000] {base.py:84} INFO - Using connection ID 'snowflake_conn_nba' for task execution.
[2024-11-25T23:52:32.880+0000] {logging_mixin.py:188} INFO - [2024-11-25T23:52:32.880+0000] {connection.py:399} INFO - Snowflake Connector for Python Version: 3.10.0, Python Version: 3.12.3, Platform: Linux-5.15.153.1-microsoft-standard-WSL2-x86_64-with-glibc2.36
[2024-11-25T23:52:32.881+0000] {logging_mixin.py:188} INFO - [2024-11-25T23:52:32.881+0000] {connection.py:1239} INFO - This connection is in OCSP Fail Open Mode. TLS Certificates would be checked for validity and revocation status. Any other Certificate Revocation related exceptions or OCSP Responder failures would be disregarded in favor of connectivity.
[2024-11-25T23:52:33.413+0000] {logging_mixin.py:188} INFO - [2024-11-25T23:52:33.411+0000] {dagbag.py:355} ERROR - Failed to import: /opt/airflow/dags/daily_data_etl.py
Traceback (most recent call last):
  File "/home/airflow/.local/lib/python3.12/site-packages/airflow/models/dagbag.py", line 351, in parse
    loader.exec_module(new_module)
  File "<frozen importlib._bootstrap_external>", line 995, in exec_module
  File "<frozen importlib._bootstrap>", line 488, in _call_with_frames_removed
  File "/opt/airflow/dags/daily_data_etl.py", line 159, in <module>
    rapid_api_key = Variable.get("rapid_api_key")
                    ^^^^^^^^^^^^^^^^^^^^^^^^^^^^^
  File "/home/airflow/.local/lib/python3.12/site-packages/airflow/models/variable.py", line 143, in get
    raise KeyError(f"Variable {key} does not exist")
KeyError: 'Variable rapid_api_key does not exist'
[2024-11-25T23:52:33.414+0000] {processor.py:842} WARNING - No viable dags retrieved from /opt/airflow/dags/daily_data_etl.py
[2024-11-25T23:52:33.423+0000] {processor.py:183} INFO - Processing /opt/airflow/dags/daily_data_etl.py took 0.577 seconds
[2024-11-25T23:53:04.316+0000] {processor.py:161} INFO - Started process (PID=287) to work on /opt/airflow/dags/daily_data_etl.py
[2024-11-25T23:53:04.317+0000] {processor.py:830} INFO - Processing file /opt/airflow/dags/daily_data_etl.py for tasks to queue
[2024-11-25T23:53:04.318+0000] {logging_mixin.py:188} INFO - [2024-11-25T23:53:04.318+0000] {dagbag.py:545} INFO - Filling up the DagBag from /opt/airflow/dags/daily_data_etl.py
[2024-11-25T23:53:04.341+0000] {logging_mixin.py:188} INFO - [2024-11-25T23:53:04.341+0000] {base.py:84} INFO - Using connection ID 'snowflake_conn_nba' for task execution.
[2024-11-25T23:53:04.342+0000] {logging_mixin.py:188} INFO - [2024-11-25T23:53:04.342+0000] {connection.py:399} INFO - Snowflake Connector for Python Version: 3.10.0, Python Version: 3.12.3, Platform: Linux-5.15.153.1-microsoft-standard-WSL2-x86_64-with-glibc2.36
[2024-11-25T23:53:04.343+0000] {logging_mixin.py:188} INFO - [2024-11-25T23:53:04.343+0000] {connection.py:1239} INFO - This connection is in OCSP Fail Open Mode. TLS Certificates would be checked for validity and revocation status. Any other Certificate Revocation related exceptions or OCSP Responder failures would be disregarded in favor of connectivity.
[2024-11-25T23:53:04.824+0000] {logging_mixin.py:188} INFO - [2024-11-25T23:53:04.820+0000] {dagbag.py:355} ERROR - Failed to import: /opt/airflow/dags/daily_data_etl.py
Traceback (most recent call last):
  File "/home/airflow/.local/lib/python3.12/site-packages/airflow/models/dagbag.py", line 351, in parse
    loader.exec_module(new_module)
  File "<frozen importlib._bootstrap_external>", line 995, in exec_module
  File "<frozen importlib._bootstrap>", line 488, in _call_with_frames_removed
  File "/opt/airflow/dags/daily_data_etl.py", line 159, in <module>
    rapid_api_key = Variable.get("rapid_api_key")
                    ^^^^^^^^^^^^^^^^^^^^^^^^^^^^^
  File "/home/airflow/.local/lib/python3.12/site-packages/airflow/models/variable.py", line 143, in get
    raise KeyError(f"Variable {key} does not exist")
KeyError: 'Variable rapid_api_key does not exist'
[2024-11-25T23:53:04.825+0000] {processor.py:842} WARNING - No viable dags retrieved from /opt/airflow/dags/daily_data_etl.py
[2024-11-25T23:53:04.834+0000] {processor.py:183} INFO - Processing /opt/airflow/dags/daily_data_etl.py took 0.522 seconds
[2024-11-25T23:53:35.731+0000] {processor.py:161} INFO - Started process (PID=303) to work on /opt/airflow/dags/daily_data_etl.py
[2024-11-25T23:53:35.732+0000] {processor.py:830} INFO - Processing file /opt/airflow/dags/daily_data_etl.py for tasks to queue
[2024-11-25T23:53:35.734+0000] {logging_mixin.py:188} INFO - [2024-11-25T23:53:35.733+0000] {dagbag.py:545} INFO - Filling up the DagBag from /opt/airflow/dags/daily_data_etl.py
[2024-11-25T23:53:35.756+0000] {logging_mixin.py:188} INFO - [2024-11-25T23:53:35.756+0000] {base.py:84} INFO - Using connection ID 'snowflake_conn_nba' for task execution.
[2024-11-25T23:53:35.758+0000] {logging_mixin.py:188} INFO - [2024-11-25T23:53:35.757+0000] {connection.py:399} INFO - Snowflake Connector for Python Version: 3.10.0, Python Version: 3.12.3, Platform: Linux-5.15.153.1-microsoft-standard-WSL2-x86_64-with-glibc2.36
[2024-11-25T23:53:35.758+0000] {logging_mixin.py:188} INFO - [2024-11-25T23:53:35.758+0000] {connection.py:1239} INFO - This connection is in OCSP Fail Open Mode. TLS Certificates would be checked for validity and revocation status. Any other Certificate Revocation related exceptions or OCSP Responder failures would be disregarded in favor of connectivity.
[2024-11-25T23:53:36.229+0000] {logging_mixin.py:188} INFO - [2024-11-25T23:53:36.226+0000] {dagbag.py:355} ERROR - Failed to import: /opt/airflow/dags/daily_data_etl.py
Traceback (most recent call last):
  File "/home/airflow/.local/lib/python3.12/site-packages/airflow/models/dagbag.py", line 351, in parse
    loader.exec_module(new_module)
  File "<frozen importlib._bootstrap_external>", line 995, in exec_module
  File "<frozen importlib._bootstrap>", line 488, in _call_with_frames_removed
  File "/opt/airflow/dags/daily_data_etl.py", line 159, in <module>
    rapid_api_key = Variable.get("rapid_api_key")
                    ^^^^^^^^^^^^^^^^^^^^^^^^^^^^^
  File "/home/airflow/.local/lib/python3.12/site-packages/airflow/models/variable.py", line 143, in get
    raise KeyError(f"Variable {key} does not exist")
KeyError: 'Variable rapid_api_key does not exist'
[2024-11-25T23:53:36.230+0000] {processor.py:842} WARNING - No viable dags retrieved from /opt/airflow/dags/daily_data_etl.py
[2024-11-25T23:53:36.239+0000] {processor.py:183} INFO - Processing /opt/airflow/dags/daily_data_etl.py took 0.513 seconds
[2024-11-25T23:54:06.297+0000] {processor.py:161} INFO - Started process (PID=319) to work on /opt/airflow/dags/daily_data_etl.py
[2024-11-25T23:54:06.297+0000] {processor.py:830} INFO - Processing file /opt/airflow/dags/daily_data_etl.py for tasks to queue
[2024-11-25T23:54:06.299+0000] {logging_mixin.py:188} INFO - [2024-11-25T23:54:06.299+0000] {dagbag.py:545} INFO - Filling up the DagBag from /opt/airflow/dags/daily_data_etl.py
[2024-11-25T23:54:06.324+0000] {logging_mixin.py:188} INFO - [2024-11-25T23:54:06.323+0000] {base.py:84} INFO - Using connection ID 'snowflake_conn_nba' for task execution.
[2024-11-25T23:54:06.325+0000] {logging_mixin.py:188} INFO - [2024-11-25T23:54:06.325+0000] {connection.py:399} INFO - Snowflake Connector for Python Version: 3.10.0, Python Version: 3.12.3, Platform: Linux-5.15.153.1-microsoft-standard-WSL2-x86_64-with-glibc2.36
[2024-11-25T23:54:06.326+0000] {logging_mixin.py:188} INFO - [2024-11-25T23:54:06.325+0000] {connection.py:1239} INFO - This connection is in OCSP Fail Open Mode. TLS Certificates would be checked for validity and revocation status. Any other Certificate Revocation related exceptions or OCSP Responder failures would be disregarded in favor of connectivity.
[2024-11-25T23:54:06.861+0000] {logging_mixin.py:188} INFO - [2024-11-25T23:54:06.859+0000] {dagbag.py:355} ERROR - Failed to import: /opt/airflow/dags/daily_data_etl.py
Traceback (most recent call last):
  File "/home/airflow/.local/lib/python3.12/site-packages/airflow/models/dagbag.py", line 351, in parse
    loader.exec_module(new_module)
  File "<frozen importlib._bootstrap_external>", line 995, in exec_module
  File "<frozen importlib._bootstrap>", line 488, in _call_with_frames_removed
  File "/opt/airflow/dags/daily_data_etl.py", line 159, in <module>
    rapid_api_key = Variable.get("rapid_api_key")
                    ^^^^^^^^^^^^^^^^^^^^^^^^^^^^^
  File "/home/airflow/.local/lib/python3.12/site-packages/airflow/models/variable.py", line 143, in get
    raise KeyError(f"Variable {key} does not exist")
KeyError: 'Variable rapid_api_key does not exist'
[2024-11-25T23:54:06.862+0000] {processor.py:842} WARNING - No viable dags retrieved from /opt/airflow/dags/daily_data_etl.py
[2024-11-25T23:54:06.870+0000] {processor.py:183} INFO - Processing /opt/airflow/dags/daily_data_etl.py took 0.578 seconds
[2024-11-25T23:54:37.160+0000] {processor.py:161} INFO - Started process (PID=335) to work on /opt/airflow/dags/daily_data_etl.py
[2024-11-25T23:54:37.161+0000] {processor.py:830} INFO - Processing file /opt/airflow/dags/daily_data_etl.py for tasks to queue
[2024-11-25T23:54:37.163+0000] {logging_mixin.py:188} INFO - [2024-11-25T23:54:37.163+0000] {dagbag.py:545} INFO - Filling up the DagBag from /opt/airflow/dags/daily_data_etl.py
[2024-11-25T23:54:37.185+0000] {logging_mixin.py:188} INFO - [2024-11-25T23:54:37.185+0000] {base.py:84} INFO - Using connection ID 'snowflake_conn_nba' for task execution.
[2024-11-25T23:54:37.186+0000] {logging_mixin.py:188} INFO - [2024-11-25T23:54:37.186+0000] {connection.py:399} INFO - Snowflake Connector for Python Version: 3.10.0, Python Version: 3.12.3, Platform: Linux-5.15.153.1-microsoft-standard-WSL2-x86_64-with-glibc2.36
[2024-11-25T23:54:37.187+0000] {logging_mixin.py:188} INFO - [2024-11-25T23:54:37.187+0000] {connection.py:1239} INFO - This connection is in OCSP Fail Open Mode. TLS Certificates would be checked for validity and revocation status. Any other Certificate Revocation related exceptions or OCSP Responder failures would be disregarded in favor of connectivity.
[2024-11-25T23:54:37.729+0000] {processor.py:840} INFO - DAG(s) 'nba_games_etl_daily' retrieved from /opt/airflow/dags/daily_data_etl.py
[2024-11-25T23:54:37.835+0000] {logging_mixin.py:188} INFO - [2024-11-25T23:54:37.834+0000] {override.py:1829} INFO - Created Permission View: can edit on DAG:nba_games_etl_daily
[2024-11-25T23:54:37.852+0000] {logging_mixin.py:188} INFO - [2024-11-25T23:54:37.852+0000] {override.py:1829} INFO - Created Permission View: can read on DAG:nba_games_etl_daily
[2024-11-25T23:54:37.862+0000] {logging_mixin.py:188} INFO - [2024-11-25T23:54:37.861+0000] {override.py:1829} INFO - Created Permission View: can delete on DAG:nba_games_etl_daily
[2024-11-25T23:54:37.864+0000] {logging_mixin.py:188} INFO - [2024-11-25T23:54:37.863+0000] {dag.py:3096} INFO - Sync 1 DAGs
[2024-11-25T23:54:37.882+0000] {logging_mixin.py:188} INFO - [2024-11-25T23:54:37.882+0000] {dag.py:3118} INFO - Creating ORM DAG for nba_games_etl_daily
[2024-11-25T23:54:37.900+0000] {logging_mixin.py:188} INFO - [2024-11-25T23:54:37.900+0000] {dag.py:3954} INFO - Setting next_dagrun for nba_games_etl_daily to 2024-11-24 02:30:00+00:00, run_after=2024-11-25 02:30:00+00:00
[2024-11-25T23:54:37.933+0000] {processor.py:183} INFO - Processing /opt/airflow/dags/daily_data_etl.py took 0.777 seconds
[2024-11-25T23:55:10.636+0000] {processor.py:161} INFO - Started process (PID=206) to work on /opt/airflow/dags/daily_data_etl.py
[2024-11-25T23:55:10.637+0000] {processor.py:830} INFO - Processing file /opt/airflow/dags/daily_data_etl.py for tasks to queue
[2024-11-25T23:55:10.638+0000] {logging_mixin.py:188} INFO - [2024-11-25T23:55:10.638+0000] {dagbag.py:545} INFO - Filling up the DagBag from /opt/airflow/dags/daily_data_etl.py
[2024-11-25T23:55:10.664+0000] {logging_mixin.py:188} INFO - [2024-11-25T23:55:10.663+0000] {base.py:84} INFO - Using connection ID 'snowflake_conn_nba' for task execution.
[2024-11-25T23:55:10.664+0000] {logging_mixin.py:188} INFO - [2024-11-25T23:55:10.664+0000] {connection.py:399} INFO - Snowflake Connector for Python Version: 3.10.0, Python Version: 3.12.3, Platform: Linux-5.15.153.1-microsoft-standard-WSL2-x86_64-with-glibc2.36
[2024-11-25T23:55:10.665+0000] {logging_mixin.py:188} INFO - [2024-11-25T23:55:10.665+0000] {connection.py:1239} INFO - This connection is in OCSP Fail Open Mode. TLS Certificates would be checked for validity and revocation status. Any other Certificate Revocation related exceptions or OCSP Responder failures would be disregarded in favor of connectivity.
[2024-11-25T23:55:11.154+0000] {processor.py:840} INFO - DAG(s) 'nba_games_etl_daily' retrieved from /opt/airflow/dags/daily_data_etl.py
[2024-11-25T23:55:11.235+0000] {logging_mixin.py:188} INFO - [2024-11-25T23:55:11.234+0000] {dag.py:3096} INFO - Sync 1 DAGs
[2024-11-25T23:55:11.250+0000] {logging_mixin.py:188} INFO - [2024-11-25T23:55:11.250+0000] {dag.py:3954} INFO - Setting next_dagrun for nba_games_etl_daily to 2024-11-24 02:30:00+00:00, run_after=2024-11-25 02:30:00+00:00
[2024-11-25T23:55:11.273+0000] {processor.py:183} INFO - Processing /opt/airflow/dags/daily_data_etl.py took 0.641 seconds
[2024-11-25T23:55:42.131+0000] {processor.py:161} INFO - Started process (PID=279) to work on /opt/airflow/dags/daily_data_etl.py
[2024-11-25T23:55:42.132+0000] {processor.py:830} INFO - Processing file /opt/airflow/dags/daily_data_etl.py for tasks to queue
[2024-11-25T23:55:42.134+0000] {logging_mixin.py:188} INFO - [2024-11-25T23:55:42.134+0000] {dagbag.py:545} INFO - Filling up the DagBag from /opt/airflow/dags/daily_data_etl.py
[2024-11-25T23:55:42.156+0000] {logging_mixin.py:188} INFO - [2024-11-25T23:55:42.156+0000] {base.py:84} INFO - Using connection ID 'snowflake_conn_nba' for task execution.
[2024-11-25T23:55:42.157+0000] {logging_mixin.py:188} INFO - [2024-11-25T23:55:42.157+0000] {connection.py:399} INFO - Snowflake Connector for Python Version: 3.10.0, Python Version: 3.12.3, Platform: Linux-5.15.153.1-microsoft-standard-WSL2-x86_64-with-glibc2.36
[2024-11-25T23:55:42.158+0000] {logging_mixin.py:188} INFO - [2024-11-25T23:55:42.158+0000] {connection.py:1239} INFO - This connection is in OCSP Fail Open Mode. TLS Certificates would be checked for validity and revocation status. Any other Certificate Revocation related exceptions or OCSP Responder failures would be disregarded in favor of connectivity.
[2024-11-25T23:55:42.597+0000] {processor.py:840} INFO - DAG(s) 'nba_games_etl_daily' retrieved from /opt/airflow/dags/daily_data_etl.py
[2024-11-25T23:55:42.662+0000] {logging_mixin.py:188} INFO - [2024-11-25T23:55:42.661+0000] {dag.py:3096} INFO - Sync 1 DAGs
[2024-11-25T23:55:42.676+0000] {logging_mixin.py:188} INFO - [2024-11-25T23:55:42.676+0000] {dag.py:3954} INFO - Setting next_dagrun for nba_games_etl_daily to 2024-11-25 02:30:00+00:00, run_after=2024-11-26 02:30:00+00:00
[2024-11-25T23:55:42.689+0000] {processor.py:183} INFO - Processing /opt/airflow/dags/daily_data_etl.py took 0.565 seconds
[2024-11-25T23:56:13.584+0000] {processor.py:161} INFO - Started process (PID=295) to work on /opt/airflow/dags/daily_data_etl.py
[2024-11-25T23:56:13.586+0000] {processor.py:830} INFO - Processing file /opt/airflow/dags/daily_data_etl.py for tasks to queue
[2024-11-25T23:56:13.589+0000] {logging_mixin.py:188} INFO - [2024-11-25T23:56:13.588+0000] {dagbag.py:545} INFO - Filling up the DagBag from /opt/airflow/dags/daily_data_etl.py
[2024-11-25T23:56:13.623+0000] {logging_mixin.py:188} INFO - [2024-11-25T23:56:13.623+0000] {base.py:84} INFO - Using connection ID 'snowflake_conn_nba' for task execution.
[2024-11-25T23:56:13.625+0000] {logging_mixin.py:188} INFO - [2024-11-25T23:56:13.625+0000] {connection.py:399} INFO - Snowflake Connector for Python Version: 3.10.0, Python Version: 3.12.3, Platform: Linux-5.15.153.1-microsoft-standard-WSL2-x86_64-with-glibc2.36
[2024-11-25T23:56:13.626+0000] {logging_mixin.py:188} INFO - [2024-11-25T23:56:13.626+0000] {connection.py:1239} INFO - This connection is in OCSP Fail Open Mode. TLS Certificates would be checked for validity and revocation status. Any other Certificate Revocation related exceptions or OCSP Responder failures would be disregarded in favor of connectivity.
[2024-11-25T23:56:14.076+0000] {processor.py:840} INFO - DAG(s) 'nba_games_etl_daily' retrieved from /opt/airflow/dags/daily_data_etl.py
[2024-11-25T23:56:14.142+0000] {logging_mixin.py:188} INFO - [2024-11-25T23:56:14.141+0000] {dag.py:3096} INFO - Sync 1 DAGs
[2024-11-25T23:56:14.158+0000] {logging_mixin.py:188} INFO - [2024-11-25T23:56:14.158+0000] {dag.py:3954} INFO - Setting next_dagrun for nba_games_etl_daily to 2024-11-25 02:30:00+00:00, run_after=2024-11-26 02:30:00+00:00
[2024-11-25T23:56:14.183+0000] {processor.py:183} INFO - Processing /opt/airflow/dags/daily_data_etl.py took 0.607 seconds
[2024-11-25T23:56:45.057+0000] {processor.py:161} INFO - Started process (PID=311) to work on /opt/airflow/dags/daily_data_etl.py
[2024-11-25T23:56:45.058+0000] {processor.py:830} INFO - Processing file /opt/airflow/dags/daily_data_etl.py for tasks to queue
[2024-11-25T23:56:45.060+0000] {logging_mixin.py:188} INFO - [2024-11-25T23:56:45.059+0000] {dagbag.py:545} INFO - Filling up the DagBag from /opt/airflow/dags/daily_data_etl.py
[2024-11-25T23:56:45.082+0000] {logging_mixin.py:188} INFO - [2024-11-25T23:56:45.082+0000] {base.py:84} INFO - Using connection ID 'snowflake_conn_nba' for task execution.
[2024-11-25T23:56:45.083+0000] {logging_mixin.py:188} INFO - [2024-11-25T23:56:45.083+0000] {connection.py:399} INFO - Snowflake Connector for Python Version: 3.10.0, Python Version: 3.12.3, Platform: Linux-5.15.153.1-microsoft-standard-WSL2-x86_64-with-glibc2.36
[2024-11-25T23:56:45.084+0000] {logging_mixin.py:188} INFO - [2024-11-25T23:56:45.084+0000] {connection.py:1239} INFO - This connection is in OCSP Fail Open Mode. TLS Certificates would be checked for validity and revocation status. Any other Certificate Revocation related exceptions or OCSP Responder failures would be disregarded in favor of connectivity.
[2024-11-25T23:56:45.564+0000] {processor.py:840} INFO - DAG(s) 'nba_games_etl_daily' retrieved from /opt/airflow/dags/daily_data_etl.py
[2024-11-25T23:56:45.625+0000] {logging_mixin.py:188} INFO - [2024-11-25T23:56:45.625+0000] {dag.py:3096} INFO - Sync 1 DAGs
[2024-11-25T23:56:45.641+0000] {logging_mixin.py:188} INFO - [2024-11-25T23:56:45.641+0000] {dag.py:3954} INFO - Setting next_dagrun for nba_games_etl_daily to 2024-11-25 02:30:00+00:00, run_after=2024-11-26 02:30:00+00:00
[2024-11-25T23:56:45.655+0000] {processor.py:183} INFO - Processing /opt/airflow/dags/daily_data_etl.py took 0.603 seconds
[2024-11-25T23:57:16.541+0000] {processor.py:161} INFO - Started process (PID=327) to work on /opt/airflow/dags/daily_data_etl.py
[2024-11-25T23:57:16.541+0000] {processor.py:830} INFO - Processing file /opt/airflow/dags/daily_data_etl.py for tasks to queue
[2024-11-25T23:57:16.543+0000] {logging_mixin.py:188} INFO - [2024-11-25T23:57:16.543+0000] {dagbag.py:545} INFO - Filling up the DagBag from /opt/airflow/dags/daily_data_etl.py
[2024-11-25T23:57:16.564+0000] {logging_mixin.py:188} INFO - [2024-11-25T23:57:16.564+0000] {base.py:84} INFO - Using connection ID 'snowflake_conn_nba' for task execution.
[2024-11-25T23:57:16.566+0000] {logging_mixin.py:188} INFO - [2024-11-25T23:57:16.565+0000] {connection.py:399} INFO - Snowflake Connector for Python Version: 3.10.0, Python Version: 3.12.3, Platform: Linux-5.15.153.1-microsoft-standard-WSL2-x86_64-with-glibc2.36
[2024-11-25T23:57:16.567+0000] {logging_mixin.py:188} INFO - [2024-11-25T23:57:16.566+0000] {connection.py:1239} INFO - This connection is in OCSP Fail Open Mode. TLS Certificates would be checked for validity and revocation status. Any other Certificate Revocation related exceptions or OCSP Responder failures would be disregarded in favor of connectivity.
[2024-11-25T23:57:17.032+0000] {processor.py:840} INFO - DAG(s) 'nba_games_etl_daily' retrieved from /opt/airflow/dags/daily_data_etl.py
[2024-11-25T23:57:17.110+0000] {logging_mixin.py:188} INFO - [2024-11-25T23:57:17.110+0000] {dag.py:3096} INFO - Sync 1 DAGs
[2024-11-25T23:57:17.125+0000] {logging_mixin.py:188} INFO - [2024-11-25T23:57:17.125+0000] {dag.py:3954} INFO - Setting next_dagrun for nba_games_etl_daily to 2024-11-25 02:30:00+00:00, run_after=2024-11-26 02:30:00+00:00
[2024-11-25T23:57:17.140+0000] {processor.py:183} INFO - Processing /opt/airflow/dags/daily_data_etl.py took 0.604 seconds
[2024-11-25T23:57:48.018+0000] {processor.py:161} INFO - Started process (PID=343) to work on /opt/airflow/dags/daily_data_etl.py
[2024-11-25T23:57:48.019+0000] {processor.py:830} INFO - Processing file /opt/airflow/dags/daily_data_etl.py for tasks to queue
[2024-11-25T23:57:48.020+0000] {logging_mixin.py:188} INFO - [2024-11-25T23:57:48.020+0000] {dagbag.py:545} INFO - Filling up the DagBag from /opt/airflow/dags/daily_data_etl.py
[2024-11-25T23:57:48.042+0000] {logging_mixin.py:188} INFO - [2024-11-25T23:57:48.042+0000] {base.py:84} INFO - Using connection ID 'snowflake_conn_nba' for task execution.
[2024-11-25T23:57:48.044+0000] {logging_mixin.py:188} INFO - [2024-11-25T23:57:48.043+0000] {connection.py:399} INFO - Snowflake Connector for Python Version: 3.10.0, Python Version: 3.12.3, Platform: Linux-5.15.153.1-microsoft-standard-WSL2-x86_64-with-glibc2.36
[2024-11-25T23:57:48.045+0000] {logging_mixin.py:188} INFO - [2024-11-25T23:57:48.045+0000] {connection.py:1239} INFO - This connection is in OCSP Fail Open Mode. TLS Certificates would be checked for validity and revocation status. Any other Certificate Revocation related exceptions or OCSP Responder failures would be disregarded in favor of connectivity.
[2024-11-25T23:57:48.570+0000] {processor.py:840} INFO - DAG(s) 'nba_games_etl_daily' retrieved from /opt/airflow/dags/daily_data_etl.py
[2024-11-25T23:57:48.631+0000] {logging_mixin.py:188} INFO - [2024-11-25T23:57:48.631+0000] {dag.py:3096} INFO - Sync 1 DAGs
[2024-11-25T23:57:48.645+0000] {logging_mixin.py:188} INFO - [2024-11-25T23:57:48.645+0000] {dag.py:3954} INFO - Setting next_dagrun for nba_games_etl_daily to 2024-11-25 02:30:00+00:00, run_after=2024-11-26 02:30:00+00:00
[2024-11-25T23:57:48.661+0000] {processor.py:183} INFO - Processing /opt/airflow/dags/daily_data_etl.py took 0.648 seconds
[2024-11-25T23:58:19.562+0000] {processor.py:161} INFO - Started process (PID=359) to work on /opt/airflow/dags/daily_data_etl.py
[2024-11-25T23:58:19.563+0000] {processor.py:830} INFO - Processing file /opt/airflow/dags/daily_data_etl.py for tasks to queue
[2024-11-25T23:58:19.564+0000] {logging_mixin.py:188} INFO - [2024-11-25T23:58:19.564+0000] {dagbag.py:545} INFO - Filling up the DagBag from /opt/airflow/dags/daily_data_etl.py
[2024-11-25T23:58:19.586+0000] {logging_mixin.py:188} INFO - [2024-11-25T23:58:19.586+0000] {base.py:84} INFO - Using connection ID 'snowflake_conn_nba' for task execution.
[2024-11-25T23:58:19.587+0000] {logging_mixin.py:188} INFO - [2024-11-25T23:58:19.587+0000] {connection.py:399} INFO - Snowflake Connector for Python Version: 3.10.0, Python Version: 3.12.3, Platform: Linux-5.15.153.1-microsoft-standard-WSL2-x86_64-with-glibc2.36
[2024-11-25T23:58:19.588+0000] {logging_mixin.py:188} INFO - [2024-11-25T23:58:19.588+0000] {connection.py:1239} INFO - This connection is in OCSP Fail Open Mode. TLS Certificates would be checked for validity and revocation status. Any other Certificate Revocation related exceptions or OCSP Responder failures would be disregarded in favor of connectivity.
[2024-11-25T23:58:20.035+0000] {processor.py:840} INFO - DAG(s) 'nba_games_etl_daily' retrieved from /opt/airflow/dags/daily_data_etl.py
[2024-11-25T23:58:20.099+0000] {logging_mixin.py:188} INFO - [2024-11-25T23:58:20.098+0000] {dag.py:3096} INFO - Sync 1 DAGs
[2024-11-25T23:58:20.113+0000] {logging_mixin.py:188} INFO - [2024-11-25T23:58:20.113+0000] {dag.py:3954} INFO - Setting next_dagrun for nba_games_etl_daily to 2024-11-25 02:30:00+00:00, run_after=2024-11-26 02:30:00+00:00
[2024-11-25T23:58:20.127+0000] {processor.py:183} INFO - Processing /opt/airflow/dags/daily_data_etl.py took 0.570 seconds
[2024-11-25T23:58:50.428+0000] {processor.py:161} INFO - Started process (PID=375) to work on /opt/airflow/dags/daily_data_etl.py
[2024-11-25T23:58:50.429+0000] {processor.py:830} INFO - Processing file /opt/airflow/dags/daily_data_etl.py for tasks to queue
[2024-11-25T23:58:50.430+0000] {logging_mixin.py:188} INFO - [2024-11-25T23:58:50.430+0000] {dagbag.py:545} INFO - Filling up the DagBag from /opt/airflow/dags/daily_data_etl.py
[2024-11-25T23:58:50.453+0000] {logging_mixin.py:188} INFO - [2024-11-25T23:58:50.453+0000] {base.py:84} INFO - Using connection ID 'snowflake_conn_nba' for task execution.
[2024-11-25T23:58:50.454+0000] {logging_mixin.py:188} INFO - [2024-11-25T23:58:50.454+0000] {connection.py:399} INFO - Snowflake Connector for Python Version: 3.10.0, Python Version: 3.12.3, Platform: Linux-5.15.153.1-microsoft-standard-WSL2-x86_64-with-glibc2.36
[2024-11-25T23:58:50.455+0000] {logging_mixin.py:188} INFO - [2024-11-25T23:58:50.455+0000] {connection.py:1239} INFO - This connection is in OCSP Fail Open Mode. TLS Certificates would be checked for validity and revocation status. Any other Certificate Revocation related exceptions or OCSP Responder failures would be disregarded in favor of connectivity.
[2024-11-25T23:58:51.088+0000] {processor.py:840} INFO - DAG(s) 'nba_games_etl_daily' retrieved from /opt/airflow/dags/daily_data_etl.py
[2024-11-25T23:58:51.099+0000] {logging_mixin.py:188} INFO - [2024-11-25T23:58:51.099+0000] {dag.py:3096} INFO - Sync 1 DAGs
[2024-11-25T23:58:51.115+0000] {logging_mixin.py:188} INFO - [2024-11-25T23:58:51.114+0000] {dag.py:3954} INFO - Setting next_dagrun for nba_games_etl_daily to 2024-11-25 02:30:00+00:00, run_after=2024-11-26 02:30:00+00:00
[2024-11-25T23:58:51.129+0000] {processor.py:183} INFO - Processing /opt/airflow/dags/daily_data_etl.py took 0.707 seconds
[2024-11-25T23:59:22.034+0000] {processor.py:161} INFO - Started process (PID=391) to work on /opt/airflow/dags/daily_data_etl.py
[2024-11-25T23:59:22.035+0000] {processor.py:830} INFO - Processing file /opt/airflow/dags/daily_data_etl.py for tasks to queue
[2024-11-25T23:59:22.036+0000] {logging_mixin.py:188} INFO - [2024-11-25T23:59:22.036+0000] {dagbag.py:545} INFO - Filling up the DagBag from /opt/airflow/dags/daily_data_etl.py
[2024-11-25T23:59:22.058+0000] {logging_mixin.py:188} INFO - [2024-11-25T23:59:22.058+0000] {base.py:84} INFO - Using connection ID 'snowflake_conn_nba' for task execution.
[2024-11-25T23:59:22.059+0000] {logging_mixin.py:188} INFO - [2024-11-25T23:59:22.059+0000] {connection.py:399} INFO - Snowflake Connector for Python Version: 3.10.0, Python Version: 3.12.3, Platform: Linux-5.15.153.1-microsoft-standard-WSL2-x86_64-with-glibc2.36
[2024-11-25T23:59:22.060+0000] {logging_mixin.py:188} INFO - [2024-11-25T23:59:22.060+0000] {connection.py:1239} INFO - This connection is in OCSP Fail Open Mode. TLS Certificates would be checked for validity and revocation status. Any other Certificate Revocation related exceptions or OCSP Responder failures would be disregarded in favor of connectivity.
[2024-11-25T23:59:22.538+0000] {processor.py:840} INFO - DAG(s) 'nba_games_etl_daily' retrieved from /opt/airflow/dags/daily_data_etl.py
[2024-11-25T23:59:22.550+0000] {logging_mixin.py:188} INFO - [2024-11-25T23:59:22.549+0000] {dag.py:3096} INFO - Sync 1 DAGs
[2024-11-25T23:59:22.566+0000] {logging_mixin.py:188} INFO - [2024-11-25T23:59:22.565+0000] {dag.py:3954} INFO - Setting next_dagrun for nba_games_etl_daily to 2024-11-25 02:30:00+00:00, run_after=2024-11-26 02:30:00+00:00
[2024-11-25T23:59:22.582+0000] {processor.py:183} INFO - Processing /opt/airflow/dags/daily_data_etl.py took 0.553 seconds
[2024-11-25T23:59:53.472+0000] {processor.py:161} INFO - Started process (PID=407) to work on /opt/airflow/dags/daily_data_etl.py
[2024-11-25T23:59:53.473+0000] {processor.py:830} INFO - Processing file /opt/airflow/dags/daily_data_etl.py for tasks to queue
[2024-11-25T23:59:53.474+0000] {logging_mixin.py:188} INFO - [2024-11-25T23:59:53.474+0000] {dagbag.py:545} INFO - Filling up the DagBag from /opt/airflow/dags/daily_data_etl.py
[2024-11-25T23:59:53.494+0000] {logging_mixin.py:188} INFO - [2024-11-25T23:59:53.494+0000] {base.py:84} INFO - Using connection ID 'snowflake_conn_nba' for task execution.
[2024-11-25T23:59:53.495+0000] {logging_mixin.py:188} INFO - [2024-11-25T23:59:53.495+0000] {connection.py:399} INFO - Snowflake Connector for Python Version: 3.10.0, Python Version: 3.12.3, Platform: Linux-5.15.153.1-microsoft-standard-WSL2-x86_64-with-glibc2.36
[2024-11-25T23:59:53.496+0000] {logging_mixin.py:188} INFO - [2024-11-25T23:59:53.496+0000] {connection.py:1239} INFO - This connection is in OCSP Fail Open Mode. TLS Certificates would be checked for validity and revocation status. Any other Certificate Revocation related exceptions or OCSP Responder failures would be disregarded in favor of connectivity.
[2024-11-25T23:59:53.948+0000] {processor.py:840} INFO - DAG(s) 'nba_games_etl_daily' retrieved from /opt/airflow/dags/daily_data_etl.py
[2024-11-25T23:59:54.010+0000] {logging_mixin.py:188} INFO - [2024-11-25T23:59:54.010+0000] {dag.py:3096} INFO - Sync 1 DAGs
[2024-11-25T23:59:54.024+0000] {logging_mixin.py:188} INFO - [2024-11-25T23:59:54.024+0000] {dag.py:3954} INFO - Setting next_dagrun for nba_games_etl_daily to 2024-11-25 02:30:00+00:00, run_after=2024-11-26 02:30:00+00:00
[2024-11-25T23:59:54.040+0000] {processor.py:183} INFO - Processing /opt/airflow/dags/daily_data_etl.py took 0.572 seconds
