[2024-11-25T23:46:10.086+0000] {processor.py:161} INFO - Started process (PID=215) to work on /opt/airflow/dags/daily_data_etl copy.py
[2024-11-25T23:46:10.087+0000] {processor.py:830} INFO - Processing file /opt/airflow/dags/daily_data_etl copy.py for tasks to queue
[2024-11-25T23:46:10.089+0000] {logging_mixin.py:188} INFO - [2024-11-25T23:46:10.089+0000] {dagbag.py:545} INFO - Filling up the DagBag from /opt/airflow/dags/daily_data_etl copy.py
[2024-11-25T23:46:10.103+0000] {logging_mixin.py:188} INFO - [2024-11-25T23:46:10.099+0000] {dagbag.py:355} ERROR - Failed to import: /opt/airflow/dags/daily_data_etl copy.py
Traceback (most recent call last):
  File "/home/airflow/.local/lib/python3.12/site-packages/airflow/models/dagbag.py", line 351, in parse
    loader.exec_module(new_module)
  File "<frozen importlib._bootstrap_external>", line 995, in exec_module
  File "<frozen importlib._bootstrap>", line 488, in _call_with_frames_removed
  File "/opt/airflow/dags/daily_data_etl copy.py", line 5, in <module>
    from airflow.utils.context import get_current_context
ImportError: cannot import name 'get_current_context' from 'airflow.utils.context' (/home/airflow/.local/lib/python3.12/site-packages/airflow/utils/context.py)
[2024-11-25T23:46:10.104+0000] {processor.py:842} WARNING - No viable dags retrieved from /opt/airflow/dags/daily_data_etl copy.py
[2024-11-25T23:46:10.119+0000] {processor.py:183} INFO - Processing /opt/airflow/dags/daily_data_etl copy.py took 0.037 seconds
[2024-11-25T23:46:40.348+0000] {processor.py:161} INFO - Started process (PID=269) to work on /opt/airflow/dags/daily_data_etl copy.py
[2024-11-25T23:46:40.350+0000] {processor.py:830} INFO - Processing file /opt/airflow/dags/daily_data_etl copy.py for tasks to queue
[2024-11-25T23:46:40.354+0000] {logging_mixin.py:188} INFO - [2024-11-25T23:46:40.353+0000] {dagbag.py:545} INFO - Filling up the DagBag from /opt/airflow/dags/daily_data_etl copy.py
[2024-11-25T23:46:40.376+0000] {logging_mixin.py:188} INFO - [2024-11-25T23:46:40.370+0000] {dagbag.py:355} ERROR - Failed to import: /opt/airflow/dags/daily_data_etl copy.py
Traceback (most recent call last):
  File "/home/airflow/.local/lib/python3.12/site-packages/airflow/models/dagbag.py", line 351, in parse
    loader.exec_module(new_module)
  File "<frozen importlib._bootstrap_external>", line 995, in exec_module
  File "<frozen importlib._bootstrap>", line 488, in _call_with_frames_removed
  File "/opt/airflow/dags/daily_data_etl copy.py", line 5, in <module>
    from airflow.utils.context import get_current_context
ImportError: cannot import name 'get_current_context' from 'airflow.utils.context' (/home/airflow/.local/lib/python3.12/site-packages/airflow/utils/context.py)
[2024-11-25T23:46:40.379+0000] {processor.py:842} WARNING - No viable dags retrieved from /opt/airflow/dags/daily_data_etl copy.py
[2024-11-25T23:46:40.415+0000] {processor.py:183} INFO - Processing /opt/airflow/dags/daily_data_etl copy.py took 0.074 seconds
